Workbook

Sheet Resumen
A1: Catálogo de plantillas por tipo de negocio
A2: Base del onboarding automático: el usuario elige su negocio y el sistema activa módulos y precarga su catálogo.
A4: Cómo funciona (3 capas)
A5: 1. Módulos: piezas que se activan o desactivan | C5: Hoja Módulos
A6: 2. Familias: grupos de negocio que comparten módulos | C6: Hojas Familias y Matriz
A7: 3. Tipos de negocio: ficha ligera por negocio | C7: Hoja Tipos de negocio
A9: Totales
A10: Módulos | B10: =COUNTA(Módulos!A2:A27) -> 26
A11: Módulos núcleo (siempre activos) | B11: =COUNTIF(Módulos!D2:D27,"Núcleo") -> 6
A12: Familias | B12: =COUNTA(Familias!A2:A17) -> 16
A13: Tipos de negocio | B13: =COUNTA('Tipos de negocio'!A2:A217) -> 216
A15: Tipos de negocio por familia
A16: Familia | B16: Tipos | C16: Módulos activos
A17: F01 · Restaurantes con servicio a mesa | B17: =COUNTIF('Tipos de negocio'!C$2:C$217,"F01") -> 18 | C17: =COUNTIF(Matriz!C2:AB2,"S") -> 12
A18: F02 · Comida rápida y para llevar | B18: =COUNTIF('Tipos de negocio'!C$2:C$217,"F02") -> 14 | C18: =COUNTIF(Matriz!C3:AB3,"S") -> 10
A19: F03 · Panadería, pastelería y producción | B19: =COUNTIF('Tipos de negocio'!C$2:C$217,"F03") -> 12 | C19: =COUNTIF(Matriz!C4:AB4,"S") -> 11
A20: F04 · Abarrotes y mercado | B20: =COUNTIF('Tipos de negocio'!C$2:C$217,"F04") -> 16 | C20: =COUNTIF(Matriz!C5:AB5,"S") -> 12
A21: F05 · Moda y retail con variantes | B21: =COUNTIF('Tipos de negocio'!C$2:C$217,"F05") -> 12 | C21: =COUNTIF(Matriz!C6:AB6,"S") -> 10
A22: F06 · Retail general | B22: =COUNTIF('Tipos de negocio'!C$2:C$217,"F06") -> 20 | C22: =COUNTIF(Matriz!C7:AB7,"S") -> 9
A23: F07 · Farmacia y salud con producto | B23: =COUNTIF('Tipos de negocio'!C$2:C$217,"F07") -> 6 | C23: =COUNTIF(Matriz!C8:AB8,"S") -> 10
A24: F08 · Tecnología y electrónica | B24: =COUNTIF('Tipos de negocio'!C$2:C$217,"F08") -> 10 | C24: =COUNTIF(Matriz!C9:AB9,"S") -> 10
A25: F09 · Ferretería y construcción | B25: =COUNTIF('Tipos de negocio'!C$2:C$217,"F09") -> 10 | C25: =COUNTIF(Matriz!C10:AB10,"S") -> 13
A26: F10 · Servicios con cita | B26: =COUNTIF('Tipos de negocio'!C$2:C$217,"F10") -> 18 | C26: =COUNTIF(Matriz!C11:AB11,"S") -> 9
A27: F11 · Talleres y servicio técnico | B27: =COUNTIF('Tipos de negocio'!C$2:C$217,"F11") -> 18 | C27: =COUNTIF(Matriz!C12:AB12,"S") -> 11
A28: F12 · Servicios profesionales | B28: =COUNTIF('Tipos de negocio'!C$2:C$217,"F12") -> 15 | C28: =COUNTIF(Matriz!C13:AB13,"S") -> 8
A29: F13 · Mayoristas y distribuidoras | B29: =COUNTIF('Tipos de negocio'!C$2:C$217,"F13") -> 12 | C29: =COUNTIF(Matriz!C14:AB14,"S") -> 12
A30: F14 · Agro y acopio | B30: =COUNTIF('Tipos de negocio'!C$2:C$217,"F14") -> 13 | C30: =COUNTIF(Matriz!C15:AB15,"S") -> 11
A31: F15 · Deporte, educación y membresías | B31: =COUNTIF('Tipos de negocio'!C$2:C$217,"F15") -> 11 | C31: =COUNTIF(Matriz!C16:AB16,"S") -> 8
A32: F16 · Hospedaje, eventos y alquiler | B32: =COUNTIF('Tipos de negocio'!C$2:C$217,"F16") -> 11 | C32: =COUNTIF(Matriz!C17:AB17,"S") -> 9
A34: Primera propuesta para revisar. Los tipos de negocio se amplían (también con IA) sin tocar los módulos.

Sheet Módulos
A1: ID | B1: Módulo | C1: Qué hace | D1: Tipo
A2: M01 | B2: Ventas (punto de venta) | C2: Registrar ventas rápidas, métodos de pago, descuentos, comprobante por WhatsApp o impreso | D2: Núcleo
A3: M02 | B3: Caja | C3: Apertura y cierre de caja, arqueo, descuadres, ingresos y retiros de efectivo | D3: Núcleo
A4: M03 | B4: Gastos | C4: Registro de gastos por categoría | D4: Núcleo
A5: M04 | B5: Inventario | C5: Stock automático (compra suma, venta resta), alertas de stock bajo, conteos | D5: Activable
A6: M05 | B6: Variantes | C6: Tallas, colores y presentaciones por producto | D6: Activable
A7: M06 | B7: Venta por peso/medida | C7: Venta por kilo, libra, litro, metro, quintal; balanza | D7: Activable
A8: M07 | B8: Código de barras | C8: Lectura EAN-13/UPC-A con cámara o lector, impresión de etiquetas | D8: Activable
A9: M08 | B9: Recetas e insumos | C9: El producto final descuenta insumos; costo por plato o producto | D9: Activable
A10: M09 | B10: Mesas y comandas | C10: Mapa de mesas, cuentas abiertas, comandas a cocina, división de cuenta | D10: Activable
A11: M10 | B11: Pedidos y delivery | C11: Pedidos para llevar o a domicilio, estados, repartidor | D11: Activable
A12: M11 | B12: Citas y agenda | C12: Agenda por profesional, recordatorios por WhatsApp | D12: Activable
... A27: M26 | B27: Reservas por fecha | C27: Reserva de habitaciones, canchas, salones o artículos por fecha/hora | D27: Activable
B29: Núcleo = activo en todos los negocios. Activable = depende de la familia.

Sheet Familias
A1: ID | B1: Familia | C1: Descripción | D1: Palabra para ítems | E1: Unidad por defecto | F1: Módulos que se activan (además del núcleo) | G1: Módulos opcionales
A2: F01 | B2: Restaurantes con servicio a mesa | C2: Atención en mesa, cocina con comandas | D2: Platos | E2: Unidad | F2: Inventario, Recetas e insumos, Mesas y comandas, Pedidos y delivery, Fiado / cuentas por cobrar, Proveedores y compras | G2: Catálogo online, Lotes y caducidad
A3: F02 | B3: Comida rápida y para llevar | C3: Venta rápida en mostrador, combos, delivery | D3: Productos | E3: Unidad | F3: Inventario, Recetas e insumos, Pedidos y delivery, Proveedores y compras | G3: Mesas y comandas, Fiado / cuentas por cobrar, Catálogo online
A4: F03 | B4: Panadería, pastelería y producción | C4: Producen lo que venden; recetas e insumos | D4: Productos | E4: Unidad | F4: Inventario, Recetas e insumos, Fiado / cuentas por cobrar, Proveedores y compras, Lotes y caducidad | G4: Pedidos y delivery, Catálogo online, Cotizaciones
A5: F04 | B5: Abarrotes y mercado | C5: Muchos productos, fiado, venta por peso | D5: Productos | E5: Unidad | F5: Inventario, Venta por peso/medida, Código de barras, Fiado / cuentas por cobrar, Proveedores y compras, Lotes y caducidad | G5: Listas de precios, Catálogo online
A6: F05 | B6: Moda y retail con variantes | C6: Tallas y colores, temporadas | D6: Productos | E6: Unidad | F6: Inventario, Variantes, Código de barras, Proveedores y compras | G6: Fiado / cuentas por cobrar, Listas de precios, Catálogo online
A7: F06 | B7: Retail general | C7: Tiendas y bazares sin variantes complejas | D7: Productos | E7: Unidad | F7: Inventario, Código de barras, Proveedores y compras | G7: Variantes, Fiado / cuentas por cobrar, Listas de precios, Catálogo online
A8: F07 | B8: Farmacia y salud con producto | C8: Lotes, caducidad, control de medicamentos | D8: Productos | E8: Unidad | F8: Inventario, Código de barras, Proveedores y compras, Lotes y caducidad | G8: Fiado / cuentas por cobrar, Listas de precios
A9: F08 | B9: Tecnología y electrónica | C9: Series/IMEI, garantías, servicio técnico | D9: Productos | E9: Unidad | F9: Inventario, Código de barras, Proveedores y compras, Series y garantías | G9: Órdenes de trabajo, Fiado / cuentas por cobrar, Cotizaciones
A10: F09 | B10: Ferretería y construcción | C10: Miles de ítems, medidas, proformas, crédito | D10: Productos | E10: Unidad | F10: Inventario, Venta por peso/medida, Código de barras, Fiado / cuentas por cobrar, Proveedores y compras, Listas de precios, Cotizaciones | G10: Catálogo online
A11: F10 | B11: Servicios con cita | C11: Belleza, bienestar y salud con agenda | D11: Servicios | E11: Servicio | F11: Citas y agenda, Servicios y comisiones, Fiado / cuentas por cobrar | G11: Inventario, Catálogo online
A12: F11 | B12: Talleres y servicio técnico | C12: Órdenes de trabajo, repuestos y mano de obra | D12: Servicios | E12: Servicio | F12: Inventario, Órdenes de trabajo, Fiado / cuentas por cobrar, Proveedores y compras, Cotizaciones | G12: Servicios y comisiones
... A17: F16 | B17: Hospedaje, eventos y alquiler | C17: Reservas por fecha y alquiler de artículos | D17: Servicios | E17: Noche | F17: Fiado / cuentas por cobrar, Cotizaciones, Reservas por fecha | G17: Inventario, Pedidos y delivery

Sheet Matriz
A1: ID | B1: Familia | C1: M01 Ventas (punto de venta) | D1: M02 Caja | E1: M03 Gastos | F1: M04 Inventario | G1: M05 Variantes | H1: M06 Venta por peso/medida | I1: M07 Código de barras | J1: M08 Recetas e insumos | K1: M09 Mesas y comandas | L1: M10 Pedidos y delivery | M1: M11 Citas y agenda | N1: M12 Servicios y comisiones | O1: M13 Órdenes de trabajo | P1: M14 Fiado / cuentas por cobrar | Q1: M15 Proveedores y compras | R1: M16 Lotes y caducidad | S1: M17 Listas de precios | T1: M18 Catálogo online | U1: M19 Facturación electrónica SRI | V1: M20 Empleados y permisos | W1: M21 Reportes y estadísticas | X1: M22 Membresías y planes | Y1: M23 Series y garantías | Z1: M24 Cotizaciones | AA1: M25 Compras a productores (acopio) | AB1: M26 Reservas por fecha
A2: F01 | B2: Restaurantes con servicio a mesa | C2: S | D2: S | E2: S | F2: S | J2: S | K2: S | L2: S | P2: S | Q2: S | R2: O | T2: O | U2: S | V2: S | W2: S
A3: F02 | B3: Comida rápida y para llevar | C3: S | D3: S | E3: S | F3: S | J3: S | K3: O | L3: S | P3: O | Q3: S | T3: O | U3: S | V3: S | W3: S
A4: F03 | B4: Panadería, pastelería y producción | C4: S | D4: S | E4: S | F4: S | J4: S | L4: O | P4: S | Q4: S | R4: S | T4: O | U4: S | V4: S | W4: S | Z4: O
A5: F04 | B5: Abarrotes y mercado | C5: S | D5: S | E5: S | F5: S | H5: S | I5: S | P5: S | Q5: S | R5: S | S5: O | T5: O | U5: S | V5: S | W5: S
A6: F05 | B6: Moda y retail con variantes | C6: S | D6: S | E6: S | F6: S | G6: S | I6: S | P6: O | Q6: S | S6: O | T6: O | U6: S | V6: S | W6: S
A7: F06 | B7: Retail general | C7: S | D7: S | E7: S | F7: S | G7: O | I7: S | P7: O | Q7: S | S7: O | T7: O | U7: S | V7: S | W7: S
A8: F07 | B8: Farmacia y salud con producto | C8: S | D8: S | E8: S | F8: S | I8: S | P8: O | Q8: S | R8: S | S8: O | U8: S | V8: S | W8: S
A9: F08 | B9: Tecnología y electrónica | C9: S | D9: S | E9: S | F9: S | I9: S | O9: O | P9: O | Q9: S | U9: S | V9: S | W9: S | Y9: S | Z9: O
A10: F09 | B10: Ferretería y construcción | C10: S | D10: S | E10: S | F10: S | H10: S | I10: S | P10: S | Q10: S | S10: S | T10: O | U10: S | V10: S | W10: S | Z10: S
A11: F10 | B11: Servicios con cita | C11: S | D11: S | E11: S | F11: O | M11: S | N11: S | P11: S | T11: O | U11: S | V11: S | W11: S
A12: F11 | B12: Talleres y servicio técnico | C12: S | D12: S | E12: S | F12: S | N12: O | O12: S | P12: S | Q12: S | U12: S | V12: S | W12: S | Z12: S
A13: F12 | B13: Servicios profesionales | C13: S | D13: S | E13: S | M13: O | P13: S | U13: S | V13: S | W13: S | Z13: S
A14: F13 | B14: Mayoristas y distribuidoras | C14: S | D14: S | E14: S | F14: S | H14: O | I14: S | P14: S | Q14: S | R14: O | S14: S | T14: O | U14: S | V14: S | W14: S | Z14: S
A15: F14 | B15: Agro y acopio | C15: S | D15: S | E15: S | F15: S | H15: S | P15: S | Q15: S | R15: S | S15: O | U15: S | V15: S | W15: S | AA15: O
A16: F15 | B16: Deporte, educación y membresías | C16: S | D16: S | E16: S | F16: O | M16: O | P16: S | U16: S | V16: S | W16: S | X16: S | AB16: O
A17: F16 | B17: Hospedaje, eventos y alquiler | C17: S | D17: S | E17: S | F17: O | L17: O | P17: S | U17: S | V17: S | W17: S | Z17: S | AB17: S
B19: S = se activa al registrarse
B20: O = se sugiere activar después
B21: Módulos núcleo activos en todas las familias

Sheet Tipos de negocio
A1: ID | B1: Tipo de negocio | C1: Familia ID | D1: Familia | E1: Sinónimos (buscador) | F1: Categorías iniciales | G1: Palabra para ítems | H1: Unidad principal | I1: Ajuste propio
A2: T001 | B2: Restaurante | C2: F01 | D2: =INDEX(Familias!B$2:B$17,MATCH(C2,Familias!A$2:A$17,0)) -> Restaurantes con servicio a mesa | E2: almuerzos, comedor | F2: Entradas; Platos fuertes; Bebidas; Postres | G2: Platos | H2: Unidad
A3: T002 | B3: Cevichería | C3: F01 | D3: =INDEX(Familias!B$2:B$17,MATCH(C3,Familias!A$2:A$17,0)) -> Restaurantes con servicio a mesa | E3: ceviche, mariscos | F3: Ceviches; Mariscos; Bebidas; Acompañantes | G3: Platos | H3: Unidad
A4: T003 | B4: Marisquería | C4: F01 | D4: =INDEX(Familias!B$2:B$17,MATCH(C4,Familias!A$2:A$17,0)) -> Restaurantes con servicio a mesa | E4: mariscos | F4: Encocados; Arroces; Ceviches; Bebidas | G4: Platos | H4: Unidad
A5: T004 | B5: Picantería | C5: F01 | D5: =INDEX(Familias!B$2:B$17,MATCH(C5,Familias!A$2:A$17,0)) -> Restaurantes con servicio a mesa | E5: comida típica | F5: Platos típicos; Bebidas; Entradas | G5: Platos | H5: Unidad
A6: T005 | B6: Asadero | C6: F01 | D6: =INDEX(Familias!B$2:B$17,MATCH(C6,Familias!A$2:A$17,0)) -> Restaurantes con servicio a mesa | E6: pollo asado, parrilla | F6: Pollos; Parrilladas; Acompañantes; Bebidas | G6: Platos | H6: Unidad
A7: T006 | B7: Parrillada / steakhouse | C7: F01 | D7: =INDEX(Familias!B$2:B$17,MATCH(C7,Familias!A$2:A$17,0)) -> Restaurantes con servicio a mesa | E7: carnes, parrilla | F7: Cortes; Parrilladas; Guarniciones; Bebidas | G7: Platos | H7: Unidad
A8: T007 | B8: Chifa | C8: F01 | D8: =INDEX(Familias!B$2:B$17,MATCH(C8,Familias!A$2:A$17,0)) -> Restaurantes con servicio a mesa | E8: comida china | F8: Arroces; Tallarines; Sopas; Bebidas | G8: Platos | H8: Unidad
A9: T008 | B9: Pizzería | C9: F01 | D9: =INDEX(Familias!B$2:B$17,MATCH(C9,Familias!A$2:A$17,0)) -> Restaurantes con servicio a mesa | E9: pizza | F9: Pizzas; Entradas; Bebidas; Postres | G9: Platos | H9: Unidad | I9: Tamaños de pizza como variantes
A10: T009 | B10: Restaurante de almuerzos (menú del día) | C10: F01 | D10: =INDEX(Familias!B$2:B$17,MATCH(C10,Familias!A$2:A$17,0)) -> Restaurantes con servicio a mesa | E10: almuerzos ejecutivos, comedor popular | F10: Almuerzos; Meriendas; Jugos | G10: Platos | H10: Unidad | I10: Menú del día cambiante
A11: T010 | B11: Encebollados y desayunos | C11: F01 | D11: =INDEX(Familias!B$2:B$17,MATCH(C11,Familias!A$2:A$17,0)) -> Restaurantes con servicio a mesa | E11: encebollado, bolones | F11: Encebollados; Bolones; Desayunos; Bebidas | G11: Platos | H11: Unidad
A12: T011 | B12: Fritadería / hornado | C12: F01 | D12: =INDEX(Familias!B$2:B$17,MATCH(C12,Familias!A$2:A$17,0)) -> Restaurantes con servicio a mesa | E12: fritada, hornado | F12: Fritada; Hornado; Acompañantes; Bebidas | G12: Platos | H12: Unidad
A13: T012 | B13: Sushi / comida japonesa | C13: F01 | D13: =INDEX(Familias!B$2:B$17,MATCH(C13,Familias!A$2:A$17,0)) -> Restaurantes con servicio a mesa | E13: sushi | F13: Rolls; Entradas; Bebidas | G13: Platos | H13: Unidad
A14: T013 | B14: Restaurante vegetariano | C14: F01 | D14: =INDEX(Familias!B$2:B$17,MATCH(C14,Familias!A$2:A$17,0)) -> Restaurantes con servicio a mesa | E14: vegano | F14: Platos; Ensaladas; Jugos; Postres | G14: Platos | H14: Unidad
A15: T014 | B15: Bar / cantina | C15: F01 | D15: =INDEX(Familias!B$2:B$17,MATCH(C15,Familias!A$2:A$17,0)) -> Restaurantes con servicio a mesa | E15: bar, cervecería | F15: Cervezas; Licores; Cócteles; Piqueos | G15: Platos | H15: Unidad
A16: T015 | B16: Discoteca | C16: F01 | D16: =INDEX(Familias!B$2:B$17,MATCH(C16,Familias!A$2:A$17,0)) -> Restaurantes con servicio a mesa | E16: club nocturno | F16: Botellas; Tragos; Cervezas; Entradas/cover | G16: Platos | H16: Unidad
A17: T016 | B17: Karaoke | C17: F01 | D17: =INDEX(Familias!B$2:B$17,MATCH(C17,Familias!A$2:A$17,0)) -> Restaurantes con servicio a mesa | E17: karaoke bar | F17: Bebidas; Piqueos; Horas de sala | G17: Platos | H17: Unidad
A18: T017 | B18: Restaurante de comida internacional | C18: F01 | D18: =INDEX(Familias!B$2:B$17,MATCH(C18,Familias!A$2:A$17,0)) -> Restaurantes con servicio a mesa | E18: mexicana, italiana | F18: Entradas; Platos fuertes; Bebidas; Postres | G18: Platos | H18: Unidad
A19: T018 | B19: Restaurante de hostería / campestre | C19: F01 | D19: =INDEX(Familias!B$2:B$17,MATCH(C19,Familias!A$2:A$17,0)) -> Restaurantes con servicio a mesa | E19: campestre | F19: Platos típicos; Parrilladas; Bebidas | G19: Platos | H19: Unidad
A20: T019 | B20: Comida rápida | C20: F02 | D20: =INDEX(Familias!B$2:B$17,MATCH(C20,Familias!A$2:A$17,0)) -> Comida rápida y para llevar | E20: fast food | F20: Hamburguesas; Hot dogs; Combos; Bebidas | G20: Productos | H20: Unidad
A21: T020 | B21: Hamburguesería | C21: F02 | D21: =INDEX(Familias!B$2:B$17,MATCH(C21,Familias!A$2:A$17,0)) -> Comida rápida y para llevar | E21: hamburguesas | F21: Hamburguesas; Papas; Combos; Bebidas | G21: Productos | H21: Unidad
A22: T021 | B22: Salchipapería | C22: F02 | D22: =INDEX(Familias!B$2:B$17,MATCH(C22,Familias!A$2:A$17,0)) -> Comida rápida y para llevar | E22: salchipapas | F22: Salchipapas; Combos; Bebidas | G22: Productos | H22: Unidad
... A34: T033 | B34: Panadería | C34: F03 | D34: =INDEX(Familias!B$2:B$17,MATCH(C34,Familias!A$2:A$17,0)) -> Panadería, pastelería y producción | E34: pan | F34: Panes; Pasteles; Bebidas; Lácteos | G34: Productos | H34: Unidad
A35: T034 | B35: Pastelería | C35: F03 | D35: =INDEX(Familias!B$2:B$17,MATCH(C35,Familias!A$2:A$17,0)) -> Panadería, pastelería y producción | E35: tortas, repostería | F35: Tortas; Postres; Bocaditos; Pedidos especiales | G35: Productos | H35: Unidad | I35: Pedidos con anticipo
A36: T035 | B36: Repostería en casa | C36: F03 | D36: =INDEX(Familias!B$2:B$17,MATCH(C36,Familias!A$2:A$17,0)) -> Panadería, pastelería y producción | E36: tortas por encargo | F36: Tortas; Cupcakes; Postres | G36: Productos | H36: Unidad | I36: Pedidos con anticipo
A37: T036 | B37: Chocolatería artesanal | C37: F03 | D37: =INDEX(Familias!B$2:B$17,MATCH(C37,Familias!A$2:A$17,0)) -> Panadería, pastelería y producción | E37: chocolates, cacao | F37: Barras; Bombones; Bebidas de cacao | G37: Productos | H37: Unidad
A38: T037 | B38: Fábrica de helados | C38: F03 | D38: =INDEX(Familias!B$2:B$17,MATCH(C38,Familias!A$2:A$17,0)) -> Panadería, pastelería y producción | E38: paletas | F38: Paletas; Litros; Conos | G38: Productos | H38: Unidad
A39: T038 | B39: Producción de snacks | C39: F03 | D39: =INDEX(Familias!B$2:B$17,MATCH(C39,Familias!A$2:A$17,0)) -> Panadería, pastelería y producción | E39: chifles, maduritos | F39: Chifles; Snacks; Paquetes | G39: Productos | H39: Unidad
A40: T039 | B40: Embutidos artesanales | C40: F03 | D40: =INDEX(Familias!B$2:B$17,MATCH(C40,Familias!A$2:A$17,0)) -> Panadería, pastelería y producción | E40: chorizos | F40: Embutidos; Carnes curadas | G40: Productos | H40: Kilo
A41: T040 | B41: Quesera / lácteos artesanales | C41: F03 | D41: =INDEX(Familias!B$2:B$17,MATCH(C41,Familias!A$2:A$17,0)) -> Panadería, pastelería y producción | E41: quesos, yogurt | F41: Quesos; Yogurt; Leche | G41: Productos | H41: Kilo
A42: T041 | B42: Cervecería artesanal | C42: F03 | D42: =INDEX(Familias!B$2:B$17,MATCH(C42,Familias!A$2:A$17,0)) -> Panadería, pastelería y producción | E42: cerveza artesanal | F42: Cervezas; Growlers; Barriles | G42: Productos | H42: Litro
A43: T042 | B43: Licores artesanales | C43: F03 | D43: =INDEX(Familias!B$2:B$17,MATCH(C43,Familias!A$2:A$17,0)) -> Panadería, pastelería y producción | E43: destilería | F43: Licores; Botellas | G43: Productos | H43: Botella
A44: T043 | B44: Mermeladas y conservas | C44: F03 | D44: =INDEX(Familias!B$2:B$17,MATCH(C44,Familias!A$2:A$17,0)) -> Panadería, pastelería y producción | E44: conservas | F44: Mermeladas; Conservas; Salsas | G44: Productos | H44: Unidad
A45: T044 | B45: Catering | C45: F03 | D45: =INDEX(Familias!B$2:B$17,MATCH(C45,Familias!A$2:A$17,0)) -> Panadería, pastelería y producción | E45: comida para eventos | F45: Menús; Bocaditos; Servicio | G45: Productos | H45: Unidad | I45: Cotizaciones por evento
A46: T045 | B46: Tienda de barrio | C46: F04 | D46: =INDEX(Familias!B$2:B$17,MATCH(C46,Familias!A$2:A$17,0)) -> Abarrotes y mercado | E46: tienda, abarrotes | F46: Abarrotes; Bebidas; Lácteos; Aseo; Snacks | G46: Productos | H46: Unidad
A47: T046 | B47: Minimarket | C47: F04 | D47: =INDEX(Familias!B$2:B$17,MATCH(C47,Familias!A$2:A$17,0)) -> Abarrotes y mercado | E47: minisúper | F47: Abarrotes; Bebidas; Lácteos; Aseo; Congelados | G47: Productos | H47: Unidad
A48: T047 | B48: Supermercado pequeño | C48: F04 | D48: =INDEX(Familias!B$2:B$17,MATCH(C48,Familias!A$2:A$17,0)) -> Abarrotes y mercado | E48: autoservicio | F48: Abarrotes; Frutas y verduras; Carnes; Aseo; Bebidas | G48: Productos | H48: Unidad
A49: T048 | B49: Despensa / víveres | C49: F04 | D49: =INDEX(Familias!B$2:B$17,MATCH(C49,Familias!A$2:A$17,0)) -> Abarrotes y mercado | E49: víveres | F49: Granos; Aceites; Enlatados; Aseo | G49: Productos | H49: Unidad
A50: T049 | B50: Frutería y verdulería | C50: F04 | D50: =INDEX(Familias!B$2:B$17,MATCH(C50,Familias!A$2:A$17,0)) -> Abarrotes y mercado | E50: frutas y verduras | F50: Frutas; Verduras; Tubérculos | G50: Productos | H50: Kilo
A51: T050 | B51: Carnicería / tercena | C51: F04 | D51: =INDEX(Familias!B$2:B$17,MATCH(C51,Familias!A$2:A$17,0)) -> Abarrotes y mercado | E51: carnes, tercena | F51: Res; Cerdo; Pollo; Embutidos | G51: Productos | H51: Libra
...

Sheet Fichas ejemplo
A1: Tipo de negocio | B1: Categoría | C1: Producto / servicio de ejemplo | D1: Unidad / variantes
A2: Tienda de barrio | B2: Abarrotes | C2: Arroz 1 kg | D2: Unidad
A3: Tienda de barrio | B3: Abarrotes | C3: Azúcar 1 kg | D3: Unidad
A4: Tienda de barrio | B4: Abarrotes | C4: Aceite 1 L | D4: Unidad
A5: Tienda de barrio | B5: Abarrotes | C5: Atún en lata | D5: Unidad
A6: Tienda de barrio | B6: Bebidas | C6: Gaseosa 1.35 L | D6: Unidad
A7: Tienda de barrio | B7: Bebidas | C7: Agua 625 ml | D7: Unidad
A8: Tienda de barrio | B8: Lácteos | C8: Leche 1 L | D8: Unidad
A9: Tienda de barrio | B9: Lácteos | C9: Queso fresco | D9: Libra
A10: Tienda de barrio | B10: Aseo | C10: Papel higiénico x4 | D10: Unidad
A11: Tienda de barrio | B11: Aseo | C11: Detergente 500 g | D11: Unidad
A12: Tienda de barrio | B12: Snacks | C12: Papas fritas | D12: Unidad
... A63: Tienda de ropa | B63: Accesorios | C63: Gorra | D63: Unidad
A65: Sin precios: el usuario pone los suyos o la IA sugiere referencias durante el alta. Estas 6 fichas muestran el formato; el resto se genera igual.

Sheet Flujo de registro
A1: Paso | B1: Pantalla | C1: Qué ve o responde el usuario | D1: Qué hace el sistema
A2: 1 | B2: Número de celular | C2: ¿Cuál es tu número? | D2: Envía un código por WhatsApp; crea el usuario sin contraseña
A3: 2 | B3: Código | C3: Ingresa el código de 6 dígitos | D3: Valida y abre sesión
A4: 3 | B4: Tipo de negocio | C4: ¿Qué negocio tienes? (buscador con sugerencias) | D4: Busca por nombre y sinónimos en la hoja Tipos de negocio; si no hay coincidencia, la IA asigna la familia más cercana y genera la ficha
A5: 4 | B5: Nombre del negocio | C5: ¿Cómo se llama tu negocio? | D5: Crea el negocio y aplica la familia: activa los módulos marcados S
A6: 5 | B6: RUC (opcional) | C6: ¿Tienes RUC? (se puede saltar) | D6: Consulta el SRI: razón social, régimen RIMPE o general, dirección; deja lista la facturación
A7: 6 | B7: Carga inicial | C7: (automático) | D7: Crea categorías y productos de ejemplo de la ficha, unidades, vocabulario y métodos de pago de Ecuador
A8: 7 | B8: Entrada al sistema | C8: (automático) | D8: Abre directo en la pantalla de venta; tour de 3 pasos según la familia
A9: 8 | B9: Después | C9: Sugerencias en el panel | D9: Ofrece activar módulos opcionales (O) cuando el uso lo indique; por ejemplo, fiado si registra ventas a crédito
